<?xml version="1.0" encoding="utf-8"?>
<!-- This URDF was automatically created by SolidWorks to URDF Exporter! Originally created by Stephen Brawner (brawner@gmail.com) 
     Commit Version: 1.6.0-4-g7f85cfe  Build Version: 1.6.7995.38578
     For more information, please see http://wiki.ros.org/sw_urdf_exporter -->
<robot
  name="Assembly_urdf_trial1">
  <link
    name="base_link">
    <inertial>
      <origin
        xyz="3.4694E-18 6.245E-17 0.073876"
        rpy="0 0 0" />
      <mass
        value="17.147" />
      <inertia
        ixx="0.192"
        ixy="4.9423E-10"
        ixz="-1.1133E-18"
        iyy="0.192"
        iyz="2.525E-17"
        izz="0.29544" />
    </inertial>
    <visual>
      <origin
        xyz="0 0 0"
        rpy="0 0 0" />
      <geometry>
        <mesh
          filename="package://Assembly_urdf_trial1/meshes/base_link.STL" />
      </geometry>
      <material
        name="">
        <color
          rgba="0.79216 0.81961 0.93333 1" />
      </material>
    </visual>
    <collision>
      <origin
        xyz="0 0 0"
        rpy="0 0 0" />
      <geometry>
        <mesh
          filename="package://Assembly_urdf_trial1/meshes/base_link.STL" />
      </geometry>
    </collision>
  </link>
  <link
    name="Lni_1">
    <inertial>
      <origin
        xyz="-7.8988E-11 -2.5709E-14 0.31047"
        rpy="0 0 0" />
      <mass
        value="3.0905" />
      <inertia
        ixx="0.025388"
        ixy="-1.4177E-12"
        ixz="-7.4535E-12"
        iyy="0.026302"
        iyz="-2.53E-15"
        izz="0.019632" />
    </inertial>
    <visual>
      <origin
        xyz="0 0 0"
        rpy="0 0 0" />
      <geometry>
        <mesh
          filename="package://Assembly_urdf_trial1/meshes/Lni_1.STL" />
      </geometry>
      <material
        name="">
        <color
          rgba="1 1 1 1" />
      </material>
    </visual>
    <collision>
      <origin
        xyz="0 0 0"
        rpy="0 0 0" />
      <geometry>
        <mesh
          filename="package://Assembly_urdf_trial1/meshes/Lni_1.STL" />
      </geometry>
    </collision>
  </link>
  <joint
    name="Joint_1"
    type="revolute">
    <origin
      xyz="0 0 0"
      rpy="0 0 0" />
    <parent
      link="base_link" />
    <child
      link="Lni_1" />
    <axis
      xyz="0 0 1" />
    <limit
      lower="0"
      upper="3.14"
      effort="300"
      velocity="3" />
  </joint>
  <link
    name="Link_2">
    <inertial>
      <origin
        xyz="-1.7347E-17 -1.3878E-17 0.57252"
        rpy="0 0 0" />
      <mass
        value="5.5867" />
      <inertia
        ixx="0.12911"
        ixy="6.6174E-21"
        ixz="3.9362E-18"
        iyy="0.12632"
        iyz="2.3297E-18"
        izz="0.011401" />
    </inertial>
    <visual>
      <origin
        xyz="0 0 0"
        rpy="0 0 0" />
      <geometry>
        <mesh
          filename="package://Assembly_urdf_trial1/meshes/Link_2.STL" />
      </geometry>
      <material
        name="">
        <color
          rgba="0.79216 0.81961 0.93333 1" />
      </material>
    </visual>
    <collision>
      <origin
        xyz="0 0 0"
        rpy="0 0 0" />
      <geometry>
        <mesh
          filename="package://Assembly_urdf_trial1/meshes/Link_2.STL" />
      </geometry>
    </collision>
  </link>
  <joint
    name="Joint_2"
    type="revolute">
    <origin
      xyz="0 0 0"
      rpy="0 0 0" />
    <parent
      link="Lni_1" />
    <child
      link="Link_2" />
    <axis
      xyz="-1 0 0" />
    <limit
      lower="-1.57"
      upper="1.57"
      effort="200"
      velocity="3" />
  </joint>
  <link
    name="Link_3">
    <inertial>
      <origin
        xyz="-5.5511E-17 -0.17893 0.805"
        rpy="0 0 0" />
      <mass
        value="2.8262" />
      <inertia
        ixx="0.025128"
        ixy="1.9707E-17"
        ixz="-3.4736E-10"
        iyy="0.0074041"
        iyz="-2.4588E-18"
        izz="0.028552" />
    </inertial>
    <visual>
      <origin
        xyz="0 0 0"
        rpy="0 0 0" />
      <geometry>
        <mesh
          filename="package://Assembly_urdf_trial1/meshes/Link_3.STL" />
      </geometry>
      <material
        name="">
        <color
          rgba="0.79216 0.81961 0.93333 1" />
      </material>
    </visual>
    <collision>
      <origin
        xyz="0 0 0"
        rpy="0 0 0" />
      <geometry>
        <mesh
          filename="package://Assembly_urdf_trial1/meshes/Link_3.STL" />
      </geometry>
    </collision>
  </link>
  <joint
    name="Joint_3"
    type="revolute">
    <origin
      xyz="0 0 0"
      rpy="0 0 0" />
    <parent
      link="Link_2" />
    <child
      link="Link_3" />
    <axis
      xyz="1 0 0" />
    <limit
      lower="0"
      upper="3.14"
      effort="200"
      velocity="3" />
  </joint>
  <link
    name="Link_4">
    <inertial>
      <origin
        xyz="-1.0408E-17 -0.35 0.75333"
        rpy="0 0 0" />
      <mass
        value="1.8097" />
      <inertia
        ixx="0.0093908"
        ixy="1.8694E-19"
        ixz="-2.4653E-19"
        iyy="0.0096102"
        iyz="5.6659E-18"
        izz="0.0023112" />
    </inertial>
    <visual>
      <origin
        xyz="0 0 0"
        rpy="0 0 0" />
      <geometry>
        <mesh
          filename="package://Assembly_urdf_trial1/meshes/Link_4.STL" />
      </geometry>
      <material
        name="">
        <color
          rgba="0.79216 0.81961 0.93333 1" />
      </material>
    </visual>
    <collision>
      <origin
        xyz="0 0 0"
        rpy="0 0 0" />
      <geometry>
        <mesh
          filename="package://Assembly_urdf_trial1/meshes/Link_4.STL" />
      </geometry>
    </collision>
  </link>
  <joint
    name="Joint_4"
    type="revolute">
    <origin
      xyz="0 0 0"
      rpy="0 0 0" />
    <parent
      link="Link_3" />
    <child
      link="Link_4" />
    <axis
      xyz="1 0 0" />
    <limit
      lower="0"
      upper="-3.14"
      effort="200"
      velocity="3" />
  </joint>
  <link
    name="Link_5">
    <inertial>
      <origin
        xyz="1.3878E-17 -0.35 0.59846"
        rpy="0 0 0" />
      <mass
        value="0.19053" />
      <inertia
        ixx="0.00011843"
        ixy="1.9664E-11"
        ixz="8.9939E-21"
        iyy="0.00022817"
        iyz="-2.3495E-19"
        izz="0.00030197" />
    </inertial>
    <visual>
      <origin
        xyz="0 0 0"
        rpy="0 0 0" />
      <geometry>
        <mesh
          filename="package://Assembly_urdf_trial1/meshes/Link_5.STL" />
      </geometry>
      <material
        name="">
        <color
          rgba="0.79216 0.81961 0.93333 1" />
      </material>
    </visual>
    <collision>
      <origin
        xyz="0 0 0"
        rpy="0 0 0" />
      <geometry>
        <mesh
          filename="package://Assembly_urdf_trial1/meshes/Link_5.STL" />
      </geometry>
    </collision>
  </link>
  <joint
    name="Joint_5"
    type="revolute">
    <origin
      xyz="0 0 0"
      rpy="0 0 0" />
    <parent
      link="Link_4" />
    <child
      link="Link_5" />
    <axis
      xyz="0 0 1" />
    <limit
      lower="0"
      upper="3.14"
      effort="200"
      velocity="3" />
  </joint>
</robot>